<?xml version="1.0"?>
<robot xmlns:xacro="http://www.ros.org/wiki/xacro">

    <xacro:macro name="handrobot_description" params="parent *origin">

    <joint name="base_joint" type="fixed">
        <xacro:insert_block name="origin" />
        <parent link = "${parent}" />
        <child link = "base" />
    </joint>

    <xacro:create_link
        link_name="base"
        xyz_offset="0 0 0"
        rpy_offset="0 0 0"
        mesh_package="handrobot_ros2_control"
        mesh_name="Base"
        color="yellow"
    />


    <!-- Joint 1 -->
    <xacro:create_link
        link_name="one_down"
        xyz_offset="0 0 0"
        rpy_offset="0 0 0"
        mesh_package="handrobot_ros2_control"
        mesh_name="OneDown"
        color="blue"
    />

    <xacro:create_link
        link_name="one_up"
        xyz_offset="0 0 0.0"
        rpy_offset="0 0 0"
        mesh_package="handrobot_ros2_control"
        mesh_name="OneUp"
        color="orange"
    />

    <joint name="joint1-bd" type="continuous">
        <parent link="base" />
        <child link= "one_down" />
        <origin xyz="0 -0.055 0.035" rpy="0.7854 0 0"/>
        <axis xyz="0 1 0"/>
        <dynamics damping="0.7"/>
        <limit effort="300" velocity="3.0"/>
    </joint>

    <joint name="joint1-du" type="continuous">
        <parent link="one_down" />
        <child link= "one_up" />
        <origin xyz="0 0 0.035" rpy="0 0 0"/>
        <axis xyz="0 1 0"/>
        <dynamics damping="0.7"/>
        <limit effort="300" velocity="3.0"/>
    </joint>


    <!-- Joint 2 -->
    <xacro:create_link
        link_name="two_down"
        xyz_offset="0 -0.02 0"
        rpy_offset="0 0 0"
        mesh_package="handrobot_ros2_control"
        mesh_name="TwoDown"
        color="blue"
    />

    <xacro:create_link
        link_name="two_middle"
        xyz_offset="0 0 0"
        rpy_offset="0 0 0"
        mesh_package="handrobot_ros2_control"
        mesh_name="TwoMiddle"
        color="green"
    />

    <xacro:create_link
        link_name="two_up"
        xyz_offset="0 0 0"
        rpy_offset="0 0 0"
        mesh_package="handrobot_ros2_control"
        mesh_name="TwoUp"
        color="orange"
    />

    <joint name="joint2-bd" type="continuous">
        <parent link="base" />
        <child link= "two_down" />
        <origin xyz="0 -0.005 0.095" rpy="0.2618 0 0"/>
        <axis xyz="0 1 0"/>
        <dynamics damping="0.7"/>
        <limit effort="300" velocity="3.0"/>
    </joint>

    <joint name="joint2-dm" type="continuous">
        <parent link="two_down" />
        <child link= "two_middle" />
        <origin xyz="0 -0.02 0.045" rpy="0 0 0"/>
        <axis xyz="0 1 0"/>
        <dynamics damping="0.7"/>
        <limit effort="300" velocity="3.0"/>
    </joint>

    <joint name="joint2-mu" type="continuous">
        <parent link="two_middle" />
        <child link= "two_up" />
        <origin xyz="0 0 0.025" rpy="0 0 0"/>
        <axis xyz="0 1 0"/>
        <dynamics damping="0.7"/>
        <limit effort="300" velocity="3.0"/>
    </joint>

    
    <!-- Joint 3 -->
    <xacro:create_link
        link_name="three_down"
        xyz_offset="0 0 0"
        rpy_offset="0 0 0"
        mesh_package="handrobot_ros2_control"
        mesh_name="ThreeDown"
        color="blue"
    />

    <xacro:create_link
        link_name="three_middle"
        xyz_offset="0 0 0"
        rpy_offset="0 0 0"
        mesh_package="handrobot_ros2_control"
        mesh_name="ThreeMiddle"
        color="green"
    />

    <xacro:create_link
        link_name="three_up"
        xyz_offset="0 0 0"
        rpy_offset="0 0 0"
        mesh_package="handrobot_ros2_control"
        mesh_name="ThreeUp"
        color="orange"
    />

    <joint name="joint3-bd" type="continuous">
        <parent link="base" />
        <child link= "three_down" />
        <origin xyz="0 0 0.1" rpy="0 0 0"/>
        <axis xyz="0 1 0"/>
        <dynamics damping="0.7"/>
        <limit effort="300" velocity="3.0"/>
    </joint>

    <joint name="joint3-dm" type="continuous">
        <parent link="three_down" />
        <child link= "three_middle" />
        <origin xyz="0 0 0.05" rpy="0 0 0"/>
        <axis xyz="0 1 0"/>
        <dynamics damping="0.7"/>
        <limit effort="300" velocity="3.0"/>
    </joint>

    <joint name="joint3-mu" type="continuous">
        <parent link="three_middle" />
        <child link= "three_up" />
        <origin xyz="0 0 0.03" rpy="0 0 0"/>
        <axis xyz="0 1 0"/>
        <dynamics damping="0.7"/>
        <limit effort="300" velocity="3.0"/>
    </joint>


    <!-- Joint 4 -->
    <xacro:create_link
        link_name="four_down"
        xyz_offset="0 0 0"
        rpy_offset="0 0 0"
        mesh_package="handrobot_ros2_control"
        mesh_name="FourDown"
        color="blue"
    />

    <xacro:create_link
        link_name="four_middle"
        xyz_offset="0 0 0"
        rpy_offset="0 0 0"
        mesh_package="handrobot_ros2_control"
        mesh_name="FourMiddle"
        color="green"
    />

    <xacro:create_link
        link_name="four_up"
        xyz_offset="0 0 0"
        rpy_offset="0 0 0"
        mesh_package="handrobot_ros2_control"
        mesh_name="FourUp"
        color="orange"
    />

    <joint name="joint4-bd" type="continuous">
        <parent link="base" />
        <child link= "four_down" />
        <origin xyz="0 0.025 0.095" rpy="-0.2618 0 0"/>
        <axis xyz="0 1 0"/>
        <dynamics damping="0.7"/>
        <limit effort="300" velocity="3.0"/>
    </joint>

    <joint name="joint4-dm" type="continuous">
        <parent link="four_down" />
        <child link= "four_middle" />
        <origin xyz="0 0 0.045" rpy="0 0 0"/>
        <axis xyz="0 1 0"/>
        <dynamics damping="0.7"/>
        <limit effort="300" velocity="3.0"/>
    </joint>

    <joint name="joint4-mu" type="continuous">
        <parent link="four_middle" />
        <child link= "four_up" />
        <origin xyz="0 0 0.03" rpy="0 0 0"/>
        <axis xyz="0 1 0"/>
        <dynamics damping="0.7"/>
        <limit effort="300" velocity="3.0"/>
    </joint>


    <!-- Joint 5 -->
    <xacro:create_link
        link_name="five_down"
        xyz_offset="0 0 0"
        rpy_offset="0 0 0"
        mesh_package="handrobot_ros2_control"
        mesh_name="FiveDown"
        color="blue"
    />

    <xacro:create_link
        link_name="five_middle"
        xyz_offset="0 0 0"
        rpy_offset="0 0 0"
        mesh_package="handrobot_ros2_control"
        mesh_name="FiveMiddle"
        color="green"
    />

    <xacro:create_link
        link_name="five_up"
        xyz_offset="0 0 0"
        rpy_offset="0 0 0"
        mesh_package="handrobot_ros2_control"
        mesh_name="FiveUp"
        color="orange"
    />

    <joint name="joint5-bd" type="continuous">
        <parent link="base" />
        <child link= "five_down" />
        <origin xyz="0 0.045 0.085" rpy="-0.524 0 0"/>
        <axis xyz="0 1 0"/>
        <dynamics damping="0.7"/>
        <limit effort="300" velocity="3.0"/>
    </joint>

    <joint name="joint5-dm" type="continuous">
        <parent link="five_down" />
        <child link= "five_middle" />
        <origin xyz="0 0 0.04" rpy="0 0 0"/>
        <axis xyz="0 1 0"/>
        <dynamics damping="0.7"/>
        <limit effort="300" velocity="3.0"/>
    </joint>

    <joint name="joint5-mu" type="continuous">
        <parent link="five_middle" />
        <child link= "five_up" />
        <origin xyz="0 0 0.02" rpy="0 0 0"/>
        <axis xyz="0 1 0"/>
        <dynamics damping="0.7"/>
        <limit effort="300" velocity="3.0"/>
    </joint>

    </xacro:macro>
</robot>